<?xml version="1.0"?>
<robot xmlns:xacro="http://www.ros.org/wiki/xacro" name="barista_robot">

<xacro:include filename="$(find barista_robot_description)/xacro/wheel.xacro" />
<xacro:include filename="$(find barista_robot_description)/xacro/standoff.xacro" />
<xacro:include filename="$(find barista_robot_description)/xacro/cup_holder_tray.xacro" />
<xacro:include filename="$(find barista_robot_description)/xacro/laser_scanner.xacro" />

<!-- Material -->
    <material name = "red">
        <color rgba = "1 0 0 0.8 "/>
    </material>

    <material name = "white">
        <color rgba = "1 1 1 1 "/>
    </material>
    
    <material name = "blue">
        <color rgba = "0 0 0.9 0.8 "/>
    </material>

    <material name = "black">
        <color rgba = "0.1 0.1 0.1 1 "/>
    </material>

    <gazebo reference="main_body">
        <material>Gazebo/Red</material>
    </gazebo>

    <gazebo reference="front_yaw_link">
        <material>Gazebo/Blue</material>
    </gazebo>

    <gazebo reference="front_roll_link">
        <material>Gazebo/Red</material>
    </gazebo>

    <gazebo reference="back_yaw_link">
        <material>Gazebo/Blue</material>
    </gazebo>

    <gazebo reference="back_roll_link">
        <material>Gazebo/Red</material>
    </gazebo>

    <gazebo reference="left_standoff_rod_1">
        <material>Gazebo/White</material>
    </gazebo>

    <gazebo reference="right_standoff_rod_1">
        <material>Gazebo/White</material>
    </gazebo>

    <gazebo reference="left_standoff_rod_2">
        <material>Gazebo/White</material>
    </gazebo>

    <gazebo reference="right_standoff_rod_2">
        <material>Gazebo/White</material>
    </gazebo>
    
    <gazebo reference="cup_holder_tray">
        <material>Gazebo/Red</material>
    </gazebo>

    <gazebo reference="laser_link">
        <material>Gazebo/Black</material>
    </gazebo>

    <link name = "base_link">
    </link>
<!-- Main body -->
    <link name = "main_body">
        <visual>
            <geometry>
                <cylinder radius = "0.178" length = "0.155"/>
            </geometry>
            <material name = "red"/>
        </visual>

        <collision>
            <geometry>
                <cylinder radius = "0.178" length = "0.155"/>
            </geometry>
        </collision>

        <inertial>
            <mass value="8"/>
            <origin rpy="0 0 0" xyz="0 0 0"/>
            <inertia ixx="0.079385" ixy="0" ixz="0" iyy="0.079385" iyz="0" izz="0.126736"/>
        </inertial>

    </link>

    <joint name = "base_main_joint" type = "fixed">
        <origin rpy = "0 0 0" xyz = "0 0 0.1127" />
        <parent link = "base_link" />
        <child link = "main_body" />
    </joint>

<!-- Wheel Joint -->
    <joint name = "main_leftwheel_joint" type = "continuous">
        <origin rpy = "0 0 0" xyz = "0 0.14 -0.0775" />
        <parent link = "main_body" />
        <child link = "left_wheel" />
        <axis rpy="0 0 0" xyz="0 1 0"/>
        <limit effort="10000" velocity="1000"/>
        <joint_properties damping="1.0" friction="1.0"/>
    </joint>

    <joint name = "main_rightwheel_joint" type = "continuous">
        <origin rpy = "0 0 0" xyz = "0 -0.14 -0.0775" />
        <parent link = "main_body" />
        <child link = "right_wheel" />
        <axis rpy="0 0 0" xyz="0 1 0"/>
        <limit effort="10000" velocity="1000"/>
        <joint_properties damping="1.0" friction="1.0"/>
    </joint>

<!-- Caster Wheel Front -->
  <link name="front_yaw_link">
      <visual>
        <origin rpy="0 1.5707 1.5707" xyz="0 0 0"/>
        <geometry>
            <cylinder radius = "0.0352" length = "0.0206"/>
        </geometry>
        <material name = "blue"/>
      </visual>

      <collision>
        <origin rpy="0 1.5707 1.5707" xyz="0 0 0"/>
        <geometry>
            <cylinder radius = "0.0352" length = "0.0206"/>
        </geometry>
      </collision>

      <inertial>
        <mass value="0.2"/>
        <origin rpy="0 1.5707 1.5707" xyz="0 0 0"/>
        <inertia ixx="0.000069" ixy="0" ixz="0" iyy="0.000124" iyz="0" izz="0.000069"/>
      </inertial>

  </link>

  <joint name="front_yaw_joint" type="continuous">
    <origin rpy="0 0 0" xyz="0.12 0 -0.0775" />
    <parent link="main_body" />
    <child link="front_yaw_link" />
    <axis xyz="0 0 1" />
    <limit effort="1000.0" velocity="100.0" />
    <dynamics damping="0.0" friction="0.1"/>
  </joint>



  <link name="front_roll_link">
      <visual>
        <origin rpy="0 1.5707 1.5707" xyz="0 0 0"/>
        <geometry>
            <cylinder radius = "0.0352" length = "0.0206"/>
        </geometry>
        <material name = "red"/>
      </visual>

      <collision>
        <origin rpy="0 1.5707 1.5707" xyz="0 0 0"/>
        <geometry>
            <cylinder radius = "0.0352" length = "0.0206"/>
        </geometry>
      </collision>

      <inertial>
        <mass value="0.2"/>
        <origin rpy="0 1.5707 1.5707" xyz="0 0 0"/>
        <inertia ixx="0.000069" ixy="0" ixz="0" iyy="0.000124" iyz="0" izz="0.000069"/>
      </inertial>
  </link>

  <joint name="front_roll_joint" type="continuous">
    <origin rpy="0 0 0" xyz="0 0 0" />
    <parent link="front_yaw_link" />
    <child link="front_roll_link" />
    <axis xyz="1 0 0" />
    <limit effort="1000.0" velocity="100.0" />
    <dynamics damping="0.0" friction="0.1"/>
  </joint>


  <link name="front_pitch_link">
    <visual>
      <origin rpy="0 1.5707 1.5707" xyz="0 0 0"/>
      <geometry>
        <sphere radius="0.0352"/>
      </geometry>
      <material name="black"/>
    </visual>

    <collision>
      <origin rpy="0 1.5707 1.5707" xyz="0 0 0"/>
      <geometry>
        <sphere radius="0.0352"/>
      </geometry>
    </collision>

    <inertial>
        <origin rpy="0 1.5707 1.5707" xyz="0 0 0"/>
        <mass value="0.2"/>
        <inertia ixx="9.9E-05" ixy="0" ixz="0" iyy="9.9E-05" iyz="0" izz="9.9E-05"/>
    </inertial>
  </link>

  <gazebo reference="front_pitch_link">
    <kp>1000000000000000000000000000.0</kp>
    <kd>1000000000000000000000000000.0</kd>
    <mu1>0.5</mu1>
    <mu2>0.5</mu2>
    <material>Gazebo/Black</material>
  </gazebo>

  <joint name="front_pitch_joint" type="continuous">
    <origin rpy="0 0 0" xyz="0 0 0" />
    <parent link="front_roll_link" />
    <child link="front_pitch_link" />
    <axis xyz="0 1 0" />
    <limit effort="1000.0" velocity="100.0" />
    <dynamics damping="0.0" friction="0.1"/>
  </joint>
<!-- Caster Wheel Back -->
  <link name="back_yaw_link">
      <visual>
        <origin rpy="0 1.5707 1.5707" xyz="0 0 0"/>
        <geometry>
            <cylinder radius = "0.0352" length = "0.0206"/>
        </geometry>
        <material name = "blue"/>
      </visual>

      <collision>
        <origin rpy="0 1.5707 1.5707" xyz="0 0 0"/>
        <geometry>
            <cylinder radius = "0.0352" length = "0.0206"/>
        </geometry>
      </collision>

      <inertial>
        <mass value="0.2"/>
        <origin rpy="0 1.5707 1.5707" xyz="0 0 0"/>
        <inertia ixx="0.000069" ixy="0" ixz="0" iyy="0.000124" iyz="0" izz="0.000069"/>
      </inertial>

  </link>

  <joint name="back_yaw_joint" type="continuous">
    <origin rpy="0 0 0" xyz="-0.12 0 -0.0775" />
    <parent link="main_body" />
    <child link="back_yaw_link" />
    <axis xyz="0 0 1" />
    <limit effort="1000.0" velocity="100.0" />
    <dynamics damping="0.0" friction="0.1"/>
  </joint>



  <link name="back_roll_link">
      <visual>
        <origin rpy="0 1.5707 1.5707" xyz="0 0 0"/>
        <geometry>
            <cylinder radius = "0.0352" length = "0.0206"/>
        </geometry>
        <material name = "red"/>
      </visual>

      <collision>
        <origin rpy="0 1.5707 1.5707" xyz="0 0 0"/>
        <geometry>
            <cylinder radius = "0.0352" length = "0.0206"/>
        </geometry>
      </collision>

      <inertial>
        <mass value="0.2"/>
        <origin rpy="0 1.5707 1.5707" xyz="0 0 0"/>
        <inertia ixx="0.000069" ixy="0" ixz="0" iyy="0.000124" iyz="0" izz="0.000069"/>
      </inertial>
  </link>

  <joint name="back_roll_joint" type="continuous">
    <origin rpy="0 0 0" xyz="0 0 0" />
    <parent link="back_yaw_link" />
    <child link="back_roll_link" />
    <axis xyz="1 0 0" />
    <limit effort="1000.0" velocity="100.0" />
    <dynamics damping="0.0" friction="0.1"/>
  </joint>


  <link name="back_pitch_link">
    <visual>
      <origin rpy="0 1.5707 1.5707" xyz="0 0 0"/>
      <geometry>
        <sphere radius="0.0352"/>
      </geometry>
      <material name="black"/>
    </visual>

    <collision>
      <origin rpy="0 1.5707 1.5707" xyz="0 0 0"/>
      <geometry>
        <sphere radius="0.0352"/>
      </geometry>
    </collision>

    <inertial>
        <origin rpy="0 1.5707 1.5707" xyz="0 0 0"/>
        <mass value="0.2"/>
        <inertia ixx="9.9E-05" ixy="0" ixz="0" iyy="9.9E-05" iyz="0" izz="9.9E-05"/>
    </inertial>
  </link>
  
  <gazebo reference="back_pitch_link">
    <kp>1000000000000000000000000000.0</kp>
    <kd>1000000000000000000000000000.0</kd>
    <mu1>0.5</mu1>
    <mu2>0.5</mu2>
    <material>Gazebo/Black</material>
  </gazebo>

  <joint name="back_pitch_joint" type="continuous">
    <origin rpy="0 0 0" xyz="0 0 0" />
    <parent link="back_roll_link" />
    <child link="back_pitch_link" />
    <axis xyz="0 1 0" />
    <limit effort="1000.0" velocity="100.0" />
    <dynamics damping="0.0" friction="0.1"/>
  </joint>
<!-- standoff rods joint  -->
    <joint name = "main_leftrod_joint_1" type = "fixed">
        <origin rpy = "0 0 0" xyz = "0.04 0.13 0.1875" />
        <parent link = "main_body" />
        <child link = "left_standoff_rod_1" />
    </joint>

    <joint name = "main_leftrod_joint_2" type = "fixed">
        <origin rpy = "0 0 0" xyz = "-0.04 0.13 0.1875" />
        <parent link = "main_body" />
        <child link = "left_standoff_rod_2" />
    </joint>

    <joint name = "main_rightrod_joint_1" type = "fixed">
        <origin rpy = "0 0 0" xyz = "0.04 -0.13 0.1875" />
        <parent link = "main_body" />
        <child link = "right_standoff_rod_1" />
    </joint>

    <joint name = "main_rightrod_joint_2" type = "fixed">
        <origin rpy = "0 0 0" xyz = "-0.04 -0.13 0.1875" />
        <parent link = "main_body" />
        <child link = "right_standoff_rod_2" />
    </joint>
<!-- Cup holder tray joint  -->
    <joint name = "main_cupholdertray_joint" type = "fixed">
        <origin rpy = "0 0 0" xyz = "0 0 0.3375" />
        <parent link = "main_body" />
        <child link = "cup_holder_tray" />
    </joint>
<!-- laser joint-->
    <joint name = "main_laserlink_joint" type = "fixed">
        <origin rpy = "0 0 0" xyz = "0 0 0.0775" />
        <parent link = "main_body" />
        <child link = "laser_link" />
    </joint>

<!-- PLUGINS -->
 
  <!-- JOINT PUBLISHER -->
  <gazebo>
    <plugin name="barstina_bot_joint_state" filename="libgazebo_ros_joint_state_publisher.so">
      <ros>
          <remapping>~/out:=joint_states</remapping>
      </ros>
      <update_rate>30</update_rate>

      <joint_name>main_leftwheel_joint</joint_name>
      <joint_name>main_rightwheel_joint</joint_name>
      <joint_name>front_yaw_joint</joint_name>
      <joint_name>back_yaw_joint</joint_name>
      <joint_name>front_roll_joint</joint_name>
      <joint_name>back_roll_joint</joint_name>
      <joint_name>front_pitch_joint</joint_name>
      <joint_name>back_pitch_joint</joint_name>

    </plugin>
  </gazebo>
  
  <!-- Differential drive -->
  <gazebo>
    <plugin filename="libgazebo_ros_diff_drive.so" name="differential_drive_controller">

      <!-- wheels -->
      <left_joint>main_leftwheel_joint</left_joint>
      <right_joint>main_rightwheel_joint</right_joint>

      <!-- kinematics -->
      <wheel_separation>0.1</wheel_separation>
      <wheel_diameter>0.07</wheel_diameter>

      <!-- limits -->
      <max_wheel_torque>1.0</max_wheel_torque>
      <max_wheel_acceleration>2.0</max_wheel_acceleration>

      <!-- output -->
      <publish_odom>true</publish_odom>
      <publish_odom_tf>true</publish_odom_tf>

      <command_topic>cmd_vel</command_topic>

      <odometry_frame>odom</odometry_frame>
      <robot_base_frame>base_link</robot_base_frame>

    </plugin>
  </gazebo>

    <xacro:arg name="include_laser" default="true" />
    <!-- Laser plugin -->
    <xacro:if value="$(arg include_laser)">
        <gazebo reference="laser_link">
            <sensor name="sensor_ray" type="ray">
                <pose>0 0 0 0 0 0</pose>
                <ray>
                <scan>
                    <horizontal>
                    <samples>200</samples>
                    <resolution>1.0</resolution>
                    <min_angle>-3.14</min_angle>
                    <max_angle>3.14</max_angle>
                    </horizontal>
                </scan>
                <range>
                    <min>0.4</min>
                    <max>5.0</max>
                </range>
                </ray>
                <always_on>true</always_on>
                <visualize>true</visualize>
                <update_rate>100.0</update_rate>
                <plugin name="laser_link" filename="libgazebo_ros_ray_sensor.so">
                <ros>
                    <remapping>~/out:=scan</remapping>
                </ros>
                <output_type>sensor_msgs/LaserScan</output_type>
                </plugin>
            </sensor>
        </gazebo>
    </xacro:if>
</robot>